2022-08-27 09:47:23,215 ERROR: Exception on /reset_password_request [POST] [in /home/gustavo/.cache/pypoetry/virtualenvs/gustavo-W69JykhD-py3.9/lib/python3.9/site-packages/flask/app.py:1741]
Traceback (most recent call last):
  File "/home/gustavo/.cache/pypoetry/virtualenvs/gustavo-W69JykhD-py3.9/lib/python3.9/site-packages/flask/app.py", line 2525, in wsgi_app
    response = self.full_dispatch_request()
  File "/home/gustavo/.cache/pypoetry/virtualenvs/gustavo-W69JykhD-py3.9/lib/python3.9/site-packages/flask/app.py", line 1822, in full_dispatch_request
    rv = self.handle_user_exception(e)
  File "/home/gustavo/.cache/pypoetry/virtualenvs/gustavo-W69JykhD-py3.9/lib/python3.9/site-packages/flask/app.py", line 1820, in full_dispatch_request
    rv = self.dispatch_request()
  File "/home/gustavo/.cache/pypoetry/virtualenvs/gustavo-W69JykhD-py3.9/lib/python3.9/site-packages/flask/app.py", line 1796, in dispatch_request
    return self.ensure_sync(self.view_functions[rule.endpoint])(**view_args)
  File "/home/gustavo/Flask-course/app/routes.py", line 174, in reset_password_request
    send_password_reset_email(user)
  File "/home/gustavo/Flask-course/app/email.py", line 14, in send_password_reset_email
    send_email('[Microblog] Reset Your Password',
  File "/home/gustavo/Flask-course/app/email.py", line 10, in send_email
    mail.send(msg)
  File "/home/gustavo/.cache/pypoetry/virtualenvs/gustavo-W69JykhD-py3.9/lib/python3.9/site-packages/flask_mail.py", line 491, in send
    with self.connect() as connection:
  File "/home/gustavo/.cache/pypoetry/virtualenvs/gustavo-W69JykhD-py3.9/lib/python3.9/site-packages/flask_mail.py", line 144, in __enter__
    self.host = self.configure_host()
  File "/home/gustavo/.cache/pypoetry/virtualenvs/gustavo-W69JykhD-py3.9/lib/python3.9/site-packages/flask_mail.py", line 158, in configure_host
    host = smtplib.SMTP(self.mail.server, self.mail.port)
  File "/home/gustavo/.pyenv/versions/3.9.9/lib/python3.9/smtplib.py", line 255, in __init__
    (code, msg) = self.connect(host, port)
  File "/home/gustavo/.pyenv/versions/3.9.9/lib/python3.9/smtplib.py", line 341, in connect
    self.sock = self._get_socket(host, port, self.timeout)
  File "/home/gustavo/.pyenv/versions/3.9.9/lib/python3.9/smtplib.py", line 312, in _get_socket
    return socket.create_connection((host, port), timeout,
  File "/home/gustavo/.pyenv/versions/3.9.9/lib/python3.9/socket.py", line 844, in create_connection
    raise err
  File "/home/gustavo/.pyenv/versions/3.9.9/lib/python3.9/socket.py", line 832, in create_connection
    sock.connect(sa)
ConnectionRefusedError: [Errno 111] Connection refused
2022-08-27 10:00:28,992 INFO: Microblog startup [in /home/gustavo/Flask-course/app/__init__.py:46]
2022-08-27 10:01:43,169 INFO: Microblog startup [in /home/gustavo/Flask-course/app/__init__.py:46]
2022-08-27 10:09:25,744 INFO: Microblog startup [in /home/gustavo/Flask-course/app/__init__.py:46]
2022-08-27 10:10:49,141 INFO: Microblog startup [in /home/gustavo/Flask-course/app/__init__.py:46]
2022-08-27 10:13:32,236 INFO: Microblog startup [in /home/gustavo/Flask-course/app/__init__.py:46]
2022-08-27 10:16:08,772 INFO: Microblog startup [in /home/gustavo/Flask-course/app/__init__.py:46]
2022-08-27 11:10:24,955 INFO: Microblog startup [in /home/gustavo/Flask-course/app/__init__.py:47]
