2022-08-31 11:10:18,216 ERROR: Exception on /search [GET] [in /home/gustavo/.cache/pypoetry/virtualenvs/gustavo-W69JykhD-py3.9/lib/python3.9/site-packages/flask/app.py:1741]
Traceback (most recent call last):
  File "/home/gustavo/.cache/pypoetry/virtualenvs/gustavo-W69JykhD-py3.9/lib/python3.9/site-packages/flask/app.py", line 2525, in wsgi_app
    response = self.full_dispatch_request()
  File "/home/gustavo/.cache/pypoetry/virtualenvs/gustavo-W69JykhD-py3.9/lib/python3.9/site-packages/flask/app.py", line 1822, in full_dispatch_request
    rv = self.handle_user_exception(e)
  File "/home/gustavo/.cache/pypoetry/virtualenvs/gustavo-W69JykhD-py3.9/lib/python3.9/site-packages/flask/app.py", line 1820, in full_dispatch_request
    rv = self.dispatch_request()
  File "/home/gustavo/.cache/pypoetry/virtualenvs/gustavo-W69JykhD-py3.9/lib/python3.9/site-packages/flask/app.py", line 1796, in dispatch_request
    return self.ensure_sync(self.view_functions[rule.endpoint])(**view_args)
  File "/home/gustavo/.cache/pypoetry/virtualenvs/gustavo-W69JykhD-py3.9/lib/python3.9/site-packages/flask_login/utils.py", line 290, in decorated_view
    return current_app.ensure_sync(func)(*args, **kwargs)
  File "/home/gustavo/Flask-course/app/main/routes.py", line 153, in search
    posts, total = Post.search(g.search_form.q.data, page,
  File "/home/gustavo/Flask-course/app/models.py", line 15, in search
    ids, total = query_index(cls.__tablename__, expression, page, per_page)
  File "/home/gustavo/Flask-course/app/search.py", line 22, in query_index
    search = current_app.elasticsearch.search(
  File "/home/gustavo/.cache/pypoetry/virtualenvs/gustavo-W69JykhD-py3.9/lib/python3.9/site-packages/elasticsearch/_sync/client/utils.py", line 414, in wrapped
    return api(*args, **kwargs)
  File "/home/gustavo/.cache/pypoetry/virtualenvs/gustavo-W69JykhD-py3.9/lib/python3.9/site-packages/elasticsearch/_sync/client/__init__.py", line 3774, in search
    return self.perform_request(  # type: ignore[return-value]
  File "/home/gustavo/.cache/pypoetry/virtualenvs/gustavo-W69JykhD-py3.9/lib/python3.9/site-packages/elasticsearch/_sync/client/_base.py", line 286, in perform_request
    meta, resp_body = self.transport.perform_request(
  File "/home/gustavo/.cache/pypoetry/virtualenvs/gustavo-W69JykhD-py3.9/lib/python3.9/site-packages/elastic_transport/_transport.py", line 329, in perform_request
    meta, raw_data = node.perform_request(
  File "/home/gustavo/.cache/pypoetry/virtualenvs/gustavo-W69JykhD-py3.9/lib/python3.9/site-packages/elastic_transport/_node/_http_urllib3.py", line 199, in perform_request
    raise err from None
elastic_transport.ConnectionError: Connection error caused by: ConnectionError(Connection error caused by: NewConnectionError(<urllib3.connection.HTTPConnection object at 0x7f21955fa130>: Failed to establish a new connection: [Errno 111] Connection refused))
2022-08-31 12:48:52,859 INFO: Microblog startup [in /home/gustavo/Flask-course/app/__init__.py:77]
2022-08-31 12:53:28,616 ERROR: Exception on /search [GET] [in /home/gustavo/.cache/pypoetry/virtualenvs/gustavo-W69JykhD-py3.9/lib/python3.9/site-packages/flask/app.py:1741]
Traceback (most recent call last):
  File "/home/gustavo/.cache/pypoetry/virtualenvs/gustavo-W69JykhD-py3.9/lib/python3.9/site-packages/flask/app.py", line 2525, in wsgi_app
    response = self.full_dispatch_request()
  File "/home/gustavo/.cache/pypoetry/virtualenvs/gustavo-W69JykhD-py3.9/lib/python3.9/site-packages/flask/app.py", line 1822, in full_dispatch_request
    rv = self.handle_user_exception(e)
  File "/home/gustavo/.cache/pypoetry/virtualenvs/gustavo-W69JykhD-py3.9/lib/python3.9/site-packages/flask/app.py", line 1820, in full_dispatch_request
    rv = self.dispatch_request()
  File "/home/gustavo/.cache/pypoetry/virtualenvs/gustavo-W69JykhD-py3.9/lib/python3.9/site-packages/flask/app.py", line 1796, in dispatch_request
    return self.ensure_sync(self.view_functions[rule.endpoint])(**view_args)
  File "/home/gustavo/.cache/pypoetry/virtualenvs/gustavo-W69JykhD-py3.9/lib/python3.9/site-packages/flask_login/utils.py", line 290, in decorated_view
    return current_app.ensure_sync(func)(*args, **kwargs)
  File "/home/gustavo/Flask-course/app/main/routes.py", line 153, in search
    posts, total = Post.search(g.search_form.q.data, page,
  File "/home/gustavo/Flask-course/app/models.py", line 15, in search
    ids, total = query_index(cls.__tablename__, expression, page, per_page)
  File "/home/gustavo/Flask-course/app/search.py", line 22, in query_index
    search = current_app.elasticsearch.search(
  File "/home/gustavo/.cache/pypoetry/virtualenvs/gustavo-W69JykhD-py3.9/lib/python3.9/site-packages/elasticsearch/_sync/client/utils.py", line 414, in wrapped
    return api(*args, **kwargs)
  File "/home/gustavo/.cache/pypoetry/virtualenvs/gustavo-W69JykhD-py3.9/lib/python3.9/site-packages/elasticsearch/_sync/client/__init__.py", line 3774, in search
    return self.perform_request(  # type: ignore[return-value]
  File "/home/gustavo/.cache/pypoetry/virtualenvs/gustavo-W69JykhD-py3.9/lib/python3.9/site-packages/elasticsearch/_sync/client/_base.py", line 286, in perform_request
    meta, resp_body = self.transport.perform_request(
  File "/home/gustavo/.cache/pypoetry/virtualenvs/gustavo-W69JykhD-py3.9/lib/python3.9/site-packages/elastic_transport/_transport.py", line 329, in perform_request
    meta, raw_data = node.perform_request(
  File "/home/gustavo/.cache/pypoetry/virtualenvs/gustavo-W69JykhD-py3.9/lib/python3.9/site-packages/elastic_transport/_node/_http_urllib3.py", line 199, in perform_request
    raise err from None
elastic_transport.ConnectionError: Connection error caused by: ConnectionError(Connection error caused by: ProtocolError(('Connection aborted.', RemoteDisconnected('Remote end closed connection without response'))))
